Traceback (most recent call last):
  File "c:\users\lenovo\anaconda3\envs\lecture-datascience\lib\site-packages\jupyter_cache\executors\utils.py", line 51, in single_nb_execution
    executenb(
  File "c:\users\lenovo\anaconda3\envs\lecture-datascience\lib\site-packages\nbclient\client.py", line 1087, in execute
    return NotebookClient(nb=nb, resources=resources, km=km, **kwargs).execute()
  File "c:\users\lenovo\anaconda3\envs\lecture-datascience\lib\site-packages\nbclient\util.py", line 74, in wrapped
    return just_run(coro(*args, **kwargs))
  File "c:\users\lenovo\anaconda3\envs\lecture-datascience\lib\site-packages\nbclient\util.py", line 53, in just_run
    return loop.run_until_complete(coro)
  File "c:\users\lenovo\anaconda3\envs\lecture-datascience\lib\asyncio\base_events.py", line 616, in run_until_complete
    return future.result()
  File "c:\users\lenovo\anaconda3\envs\lecture-datascience\lib\site-packages\nbclient\client.py", line 540, in async_execute
    await self.async_execute_cell(
  File "c:\users\lenovo\anaconda3\envs\lecture-datascience\lib\site-packages\nbclient\client.py", line 832, in async_execute_cell
    self._check_raise_for_error(cell, exec_reply)
  File "c:\users\lenovo\anaconda3\envs\lecture-datascience\lib\site-packages\nbclient\client.py", line 740, in _check_raise_for_error
    raise CellExecutionError.from_cell_and_msg(cell, exec_reply['content'])
nbclient.exceptions.CellExecutionError: An error occurred while executing the following cell:
------------------
ws = [w1, w2, ..., wend]
bs = [b1, b2, ..., bend]

def eval_mlp(X, ws, bs, f):
    """
    Evaluate MLP-given weights (ws), bias (bs) and an activation (f)

    Assumes that the same activation is applied to all hidden layers
    """
    N = len(ws) - 1

    out = X
    for i in range(N):
        out = f(__)  # replace the __

    # For this step remember python starts counting at 0!
    return out@__ + __  # replace the __
------------------

[1;31m---------------------------------------------------------------------------[0m
[1;31mNameError[0m                                 Traceback (most recent call last)
[1;32m<ipython-input-40-dd93bcf10b64>[0m in [0;36m<module>[1;34m[0m
[1;32m----> 1[1;33m [0mws[0m [1;33m=[0m [1;33m[[0m[0mw1[0m[1;33m,[0m [0mw2[0m[1;33m,[0m [1;33m...[0m[1;33m,[0m [0mwend[0m[1;33m][0m[1;33m[0m[1;33m[0m[0m
[0m[0;32m      2[0m [0mbs[0m [1;33m=[0m [1;33m[[0m[0mb1[0m[1;33m,[0m [0mb2[0m[1;33m,[0m [1;33m...[0m[1;33m,[0m [0mbend[0m[1;33m][0m[1;33m[0m[1;33m[0m[0m
[0;32m      3[0m [1;33m[0m[0m
[0;32m      4[0m [1;32mdef[0m [0meval_mlp[0m[1;33m([0m[0mX[0m[1;33m,[0m [0mws[0m[1;33m,[0m [0mbs[0m[1;33m,[0m [0mf[0m[1;33m)[0m[1;33m:[0m[1;33m[0m[1;33m[0m[0m
[0;32m      5[0m     """

[1;31mNameError[0m: name 'w1' is not defined
NameError: name 'w1' is not defined

