Traceback (most recent call last):
  File "c:\users\lenovo\anaconda3\envs\lecture-datascience\lib\site-packages\jupyter_cache\executors\utils.py", line 51, in single_nb_execution
    executenb(
  File "c:\users\lenovo\anaconda3\envs\lecture-datascience\lib\site-packages\nbclient\client.py", line 1087, in execute
    return NotebookClient(nb=nb, resources=resources, km=km, **kwargs).execute()
  File "c:\users\lenovo\anaconda3\envs\lecture-datascience\lib\site-packages\nbclient\util.py", line 74, in wrapped
    return just_run(coro(*args, **kwargs))
  File "c:\users\lenovo\anaconda3\envs\lecture-datascience\lib\site-packages\nbclient\util.py", line 53, in just_run
    return loop.run_until_complete(coro)
  File "c:\users\lenovo\anaconda3\envs\lecture-datascience\lib\asyncio\base_events.py", line 616, in run_until_complete
    return future.result()
  File "c:\users\lenovo\anaconda3\envs\lecture-datascience\lib\site-packages\nbclient\client.py", line 540, in async_execute
    await self.async_execute_cell(
  File "c:\users\lenovo\anaconda3\envs\lecture-datascience\lib\site-packages\nbclient\client.py", line 832, in async_execute_cell
    self._check_raise_for_error(cell, exec_reply)
  File "c:\users\lenovo\anaconda3\envs\lecture-datascience\lib\site-packages\nbclient\client.py", line 740, in _check_raise_for_error
    raise CellExecutionError.from_cell_and_msg(cell, exec_reply['content'])
nbclient.exceptions.CellExecutionError: An error occurred while executing the following cell:
------------------
print("Unit test running")
assert False, "Failure in unit test"
------------------

[1;31m---------------------------------------------------------------------------[0m
[1;31mAssertionError[0m                            Traceback (most recent call last)
[1;32m<ipython-input-41-13002fafc671>[0m in [0;36m<module>[1;34m[0m
[0;32m      1[0m [0mprint[0m[1;33m([0m[1;34m"Unit test running"[0m[1;33m)[0m[1;33m[0m[1;33m[0m[0m
[1;32m----> 2[1;33m [1;32massert[0m [1;32mFalse[0m[1;33m,[0m [1;34m"Failure in unit test"[0m[1;33m[0m[1;33m[0m[0m
[0m
[1;31mAssertionError[0m: Failure in unit test
AssertionError: Failure in unit test

